[2024-12-02T06:59:00.753+0000] {local_task_job_runner.py:123} INFO - ::group::Pre task execution logs
[2024-12-02T06:59:00.772+0000] {taskinstance.py:2612} INFO - Dependencies all met for dep_context=non-requeueable deps ti=<TaskInstance: Amazon_Book_Data.Create_Table_PGdb scheduled__2024-10-06T00:00:00+00:00 [queued]>
[2024-12-02T06:59:00.780+0000] {taskinstance.py:2612} INFO - Dependencies all met for dep_context=requeueable deps ti=<TaskInstance: Amazon_Book_Data.Create_Table_PGdb scheduled__2024-10-06T00:00:00+00:00 [queued]>
[2024-12-02T06:59:00.780+0000] {taskinstance.py:2865} INFO - Starting attempt 1 of 2
[2024-12-02T06:59:00.794+0000] {taskinstance.py:2888} INFO - Executing <Task(PostgresOperator): Create_Table_PGdb> on 2024-10-06 00:00:00+00:00
[2024-12-02T06:59:00.805+0000] {warnings.py:112} WARNING - /home/***/.local/lib/python3.12/site-packages/***/task/task_runner/standard_task_runner.py:70: DeprecationWarning: This process (pid=137) is multi-threaded, use of fork() may lead to deadlocks in the child.
  pid = os.fork()

[2024-12-02T06:59:00.806+0000] {standard_task_runner.py:72} INFO - Started process 186 to run task
[2024-12-02T06:59:00.808+0000] {standard_task_runner.py:104} INFO - Running: ['***', 'tasks', 'run', 'Amazon_Book_Data', 'Create_Table_PGdb', 'scheduled__2024-10-06T00:00:00+00:00', '--job-id', '84', '--raw', '--subdir', 'DAGS_FOLDER/amazon_books.py', '--cfg-path', '/tmp/tmp7i_x3byd']
[2024-12-02T06:59:00.809+0000] {standard_task_runner.py:105} INFO - Job 84: Subtask Create_Table_PGdb
[2024-12-02T06:59:00.857+0000] {task_command.py:467} INFO - Running <TaskInstance: Amazon_Book_Data.Create_Table_PGdb scheduled__2024-10-06T00:00:00+00:00 [running]> on host 9458297c348b
[2024-12-02T06:59:00.961+0000] {taskinstance.py:3131} INFO - Exporting env vars: AIRFLOW_CTX_DAG_OWNER='***' AIRFLOW_CTX_DAG_ID='Amazon_Book_Data' AIRFLOW_CTX_TASK_ID='Create_Table_PGdb' AIRFLOW_CTX_EXECUTION_DATE='2024-10-06T00:00:00+00:00' AIRFLOW_CTX_TRY_NUMBER='1' AIRFLOW_CTX_DAG_RUN_ID='scheduled__2024-10-06T00:00:00+00:00'
[2024-12-02T06:59:00.963+0000] {logging_mixin.py:190} INFO - Task instance is in running state
[2024-12-02T06:59:00.963+0000] {logging_mixin.py:190} INFO -  Previous state of the Task instance: queued
[2024-12-02T06:59:00.964+0000] {logging_mixin.py:190} INFO - Current task name:Create_Table_PGdb state:running start_date:2024-12-02 06:59:00.772675+00:00
[2024-12-02T06:59:00.964+0000] {logging_mixin.py:190} INFO - Dag name:Amazon_Book_Data and current dag run status:running
[2024-12-02T06:59:00.965+0000] {taskinstance.py:731} INFO - ::endgroup::
[2024-12-02T06:59:00.966+0000] {sql.py:266} INFO - Executing: 
    CREATE TABLE IF NOT EXISTS amazon_books (
        id SERIAL PRIMARY KEY,
        title TEXT NOT NULL,
        authors TEXT,
        price TEXT,
        rating TEXT
    );
    
[2024-12-02T06:59:00.974+0000] {base.py:84} INFO - Retrieving connection 'Amazon_Books'
[2024-12-02T06:59:00.985+0000] {base.py:84} INFO - Retrieving connection 'Amazon_Books'
[2024-12-02T06:59:00.987+0000] {taskinstance.py:3310} ERROR - Task failed with exception
Traceback (most recent call last):
  File "/home/airflow/.local/lib/python3.12/site-packages/airflow/models/taskinstance.py", line 767, in _execute_task
    result = _execute_callable(context=context, **execute_callable_kwargs)
             ^^^^^^^^^^^^^^^^^^^^^^^^^^^^^^^^^^^^^^^^^^^^^^^^^^^^^^^^^^^^^
  File "/home/airflow/.local/lib/python3.12/site-packages/airflow/models/taskinstance.py", line 733, in _execute_callable
    return ExecutionCallableRunner(
           ^^^^^^^^^^^^^^^^^^^^^^^^
  File "/home/airflow/.local/lib/python3.12/site-packages/airflow/utils/operator_helpers.py", line 252, in run
    return self.func(*args, **kwargs)
           ^^^^^^^^^^^^^^^^^^^^^^^^^^
  File "/home/airflow/.local/lib/python3.12/site-packages/airflow/models/baseoperator.py", line 406, in wrapper
    return func(self, *args, **kwargs)
           ^^^^^^^^^^^^^^^^^^^^^^^^^^^
  File "/home/airflow/.local/lib/python3.12/site-packages/airflow/providers/common/sql/operators/sql.py", line 272, in execute
    output = hook.run(
             ^^^^^^^^^
  File "/home/airflow/.local/lib/python3.12/site-packages/airflow/providers/common/sql/hooks/sql.py", line 452, in run
    with self._create_autocommit_connection(autocommit) as conn:
         ^^^^^^^^^^^^^^^^^^^^^^^^^^^^^^^^^^^^^^^^^^^^^^
  File "/usr/local/lib/python3.12/contextlib.py", line 137, in __enter__
    return next(self.gen)
           ^^^^^^^^^^^^^^
  File "/home/airflow/.local/lib/python3.12/site-packages/airflow/providers/common/sql/hooks/sql.py", line 574, in _create_autocommit_connection
    with closing(self.get_conn()) as conn:
                 ^^^^^^^^^^^^^^^
  File "/home/airflow/.local/lib/python3.12/site-packages/airflow/providers/postgres/hooks/postgres.py", line 176, in get_conn
    self.conn = psycopg2.connect(**conn_args)
                ^^^^^^^^^^^^^^^^^^^^^^^^^^^^^
  File "/home/airflow/.local/lib/python3.12/site-packages/psycopg2/__init__.py", line 122, in connect
    conn = _connect(dsn, connection_factory=connection_factory, **kwasync)
           ^^^^^^^^^^^^^^^^^^^^^^^^^^^^^^^^^^^^^^^^^^^^^^^^^^^^^^^^^^^^^^^
psycopg2.OperationalError: connection to server at "172.18.0.4", port 5432 failed: Connection refused
	Is the server running on that host and accepting TCP/IP connections?

[2024-12-02T06:59:01.002+0000] {logging_mixin.py:190} INFO - Task instance in failure state
[2024-12-02T06:59:01.003+0000] {logging_mixin.py:190} INFO - Task start:2024-12-02 06:59:00.772675+00:00 end:2024-12-02 06:59:01.002444+00:00 duration:0.229769
[2024-12-02T06:59:01.003+0000] {logging_mixin.py:190} INFO - Task:<Task(PostgresOperator): Create_Table_PGdb> dag:<DAG: Amazon_Book_Data> dagrun:<DagRun Amazon_Book_Data @ 2024-10-06 00:00:00+00:00: scheduled__2024-10-06T00:00:00+00:00, state:running, queued_at: 2024-12-02 06:57:51.556509+00:00. externally triggered: False>
[2024-12-02T06:59:01.004+0000] {logging_mixin.py:190} INFO - Failure caused by connection to server at "172.18.0.4", port 5432 failed: Connection refused
	Is the server running on that host and accepting TCP/IP connections?
[2024-12-02T06:59:01.004+0000] {taskinstance.py:1225} INFO - Marking task as UP_FOR_RETRY. dag_id=Amazon_Book_Data, task_id=Create_Table_PGdb, run_id=scheduled__2024-10-06T00:00:00+00:00, execution_date=20241006T000000, start_date=20241202T065900, end_date=20241202T065901
[2024-12-02T06:59:01.021+0000] {taskinstance.py:340} INFO - ::group::Post task execution logs
[2024-12-02T06:59:01.022+0000] {standard_task_runner.py:124} ERROR - Failed to execute job 84 for task Create_Table_PGdb (connection to server at "172.18.0.4", port 5432 failed: Connection refused
	Is the server running on that host and accepting TCP/IP connections?
; 186)
Traceback (most recent call last):
  File "/home/airflow/.local/lib/python3.12/site-packages/airflow/task/task_runner/standard_task_runner.py", line 117, in _start_by_fork
    ret = args.func(args, dag=self.dag)
          ^^^^^^^^^^^^^^^^^^^^^^^^^^^^^
  File "/home/airflow/.local/lib/python3.12/site-packages/airflow/cli/cli_config.py", line 49, in command
    return func(*args, **kwargs)
           ^^^^^^^^^^^^^^^^^^^^^
  File "/home/airflow/.local/lib/python3.12/site-packages/airflow/utils/cli.py", line 115, in wrapper
    return f(*args, **kwargs)
           ^^^^^^^^^^^^^^^^^^
  File "/home/airflow/.local/lib/python3.12/site-packages/airflow/cli/commands/task_command.py", line 483, in task_run
    task_return_code = _run_task_by_selected_method(args, _dag, ti)
                       ^^^^^^^^^^^^^^^^^^^^^^^^^^^^^^^^^^^^^^^^^^^^
  File "/home/airflow/.local/lib/python3.12/site-packages/airflow/cli/commands/task_command.py", line 256, in _run_task_by_selected_method
    return _run_raw_task(args, ti)
           ^^^^^^^^^^^^^^^^^^^^^^^
  File "/home/airflow/.local/lib/python3.12/site-packages/airflow/cli/commands/task_command.py", line 341, in _run_raw_task
    return ti._run_raw_task(
           ^^^^^^^^^^^^^^^^^
  File "/home/airflow/.local/lib/python3.12/site-packages/airflow/utils/session.py", line 97, in wrapper
    return func(*args, session=session, **kwargs)
           ^^^^^^^^^^^^^^^^^^^^^^^^^^^^^^^^^^^^^^
  File "/home/airflow/.local/lib/python3.12/site-packages/airflow/models/taskinstance.py", line 3004, in _run_raw_task
    return _run_raw_task(
           ^^^^^^^^^^^^^^
  File "/home/airflow/.local/lib/python3.12/site-packages/airflow/models/taskinstance.py", line 273, in _run_raw_task
    TaskInstance._execute_task_with_callbacks(
  File "/home/airflow/.local/lib/python3.12/site-packages/airflow/models/taskinstance.py", line 3158, in _execute_task_with_callbacks
    result = self._execute_task(context, task_orig)
             ^^^^^^^^^^^^^^^^^^^^^^^^^^^^^^^^^^^^^^
  File "/home/airflow/.local/lib/python3.12/site-packages/airflow/models/taskinstance.py", line 3182, in _execute_task
    return _execute_task(self, context, task_orig)
           ^^^^^^^^^^^^^^^^^^^^^^^^^^^^^^^^^^^^^^^
  File "/home/airflow/.local/lib/python3.12/site-packages/airflow/models/taskinstance.py", line 767, in _execute_task
    result = _execute_callable(context=context, **execute_callable_kwargs)
             ^^^^^^^^^^^^^^^^^^^^^^^^^^^^^^^^^^^^^^^^^^^^^^^^^^^^^^^^^^^^^
  File "/home/airflow/.local/lib/python3.12/site-packages/airflow/models/taskinstance.py", line 733, in _execute_callable
    return ExecutionCallableRunner(
           ^^^^^^^^^^^^^^^^^^^^^^^^
  File "/home/airflow/.local/lib/python3.12/site-packages/airflow/utils/operator_helpers.py", line 252, in run
    return self.func(*args, **kwargs)
           ^^^^^^^^^^^^^^^^^^^^^^^^^^
  File "/home/airflow/.local/lib/python3.12/site-packages/airflow/models/baseoperator.py", line 406, in wrapper
    return func(self, *args, **kwargs)
           ^^^^^^^^^^^^^^^^^^^^^^^^^^^
  File "/home/airflow/.local/lib/python3.12/site-packages/airflow/providers/common/sql/operators/sql.py", line 272, in execute
    output = hook.run(
             ^^^^^^^^^
  File "/home/airflow/.local/lib/python3.12/site-packages/airflow/providers/common/sql/hooks/sql.py", line 452, in run
    with self._create_autocommit_connection(autocommit) as conn:
         ^^^^^^^^^^^^^^^^^^^^^^^^^^^^^^^^^^^^^^^^^^^^^^
  File "/usr/local/lib/python3.12/contextlib.py", line 137, in __enter__
    return next(self.gen)
           ^^^^^^^^^^^^^^
  File "/home/airflow/.local/lib/python3.12/site-packages/airflow/providers/common/sql/hooks/sql.py", line 574, in _create_autocommit_connection
    with closing(self.get_conn()) as conn:
                 ^^^^^^^^^^^^^^^
  File "/home/airflow/.local/lib/python3.12/site-packages/airflow/providers/postgres/hooks/postgres.py", line 176, in get_conn
    self.conn = psycopg2.connect(**conn_args)
                ^^^^^^^^^^^^^^^^^^^^^^^^^^^^^
  File "/home/airflow/.local/lib/python3.12/site-packages/psycopg2/__init__.py", line 122, in connect
    conn = _connect(dsn, connection_factory=connection_factory, **kwasync)
           ^^^^^^^^^^^^^^^^^^^^^^^^^^^^^^^^^^^^^^^^^^^^^^^^^^^^^^^^^^^^^^^
psycopg2.OperationalError: connection to server at "172.18.0.4", port 5432 failed: Connection refused
	Is the server running on that host and accepting TCP/IP connections?

[2024-12-02T06:59:01.061+0000] {local_task_job_runner.py:266} INFO - Task exited with return code 1
[2024-12-02T06:59:01.074+0000] {warnings.py:112} WARNING - /home/***/.local/lib/python3.12/site-packages/***/models/baseoperator.py:1378: AirflowProviderDeprecationWarning: Call to deprecated class PostgresOperator. (Please use `***.providers.common.sql.operators.sql.SQLExecuteQueryOperator`.Also, you can provide `hook_params={'schema': <database>}`.)
  result = cls.__new__(cls)

[2024-12-02T06:59:01.090+0000] {taskinstance.py:3900} INFO - 0 downstream tasks scheduled from follow-on schedule check
[2024-12-02T06:59:01.092+0000] {local_task_job_runner.py:245} INFO - ::endgroup::
