[2024-09-26T16:19:15.265+0000] {local_task_job_runner.py:123} INFO - ::group::Pre task execution logs
[2024-09-26T16:19:15.651+0000] {taskinstance.py:2612} INFO - Dependencies all met for dep_context=non-requeueable deps ti=<TaskInstance: Amazon_Book_Data.Create_Table_PGdb scheduled__2024-06-21T00:00:00+00:00 [queued]>
[2024-09-26T16:19:15.866+0000] {taskinstance.py:2612} INFO - Dependencies all met for dep_context=requeueable deps ti=<TaskInstance: Amazon_Book_Data.Create_Table_PGdb scheduled__2024-06-21T00:00:00+00:00 [queued]>
[2024-09-26T16:19:15.867+0000] {taskinstance.py:2865} INFO - Starting attempt 1 of 2
[2024-09-26T16:19:16.230+0000] {taskinstance.py:2888} INFO - Executing <Task(PostgresOperator): Create_Table_PGdb> on 2024-06-21 00:00:00+00:00
[2024-09-26T16:19:16.771+0000] {warnings.py:112} WARNING - /home/***/.local/lib/python3.12/site-packages/***/task/task_runner/standard_task_runner.py:70: DeprecationWarning: This process (pid=1232) is multi-threaded, use of fork() may lead to deadlocks in the child.
  pid = os.fork()

[2024-09-26T16:19:16.776+0000] {standard_task_runner.py:72} INFO - Started process 1300 to run task
[2024-09-26T16:19:16.980+0000] {standard_task_runner.py:104} INFO - Running: ['***', 'tasks', 'run', 'Amazon_Book_Data', 'Create_Table_PGdb', 'scheduled__2024-06-21T00:00:00+00:00', '--job-id', '21', '--raw', '--subdir', 'DAGS_FOLDER/amazon_books.py', '--cfg-path', '/tmp/tmp1phmukmm']
[2024-09-26T16:19:16.982+0000] {standard_task_runner.py:105} INFO - Job 21: Subtask Create_Table_PGdb
[2024-09-26T16:19:20.562+0000] {task_command.py:467} INFO - Running <TaskInstance: Amazon_Book_Data.Create_Table_PGdb scheduled__2024-06-21T00:00:00+00:00 [running]> on host f04706ee9217
[2024-09-26T16:19:23.829+0000] {taskinstance.py:3131} INFO - Exporting env vars: AIRFLOW_CTX_DAG_OWNER='***' AIRFLOW_CTX_DAG_ID='Amazon_Book_Data' AIRFLOW_CTX_TASK_ID='Create_Table_PGdb' AIRFLOW_CTX_EXECUTION_DATE='2024-06-21T00:00:00+00:00' AIRFLOW_CTX_TRY_NUMBER='1' AIRFLOW_CTX_DAG_RUN_ID='scheduled__2024-06-21T00:00:00+00:00'
[2024-09-26T16:19:24.026+0000] {logging_mixin.py:190} INFO - Task instance is in running state
[2024-09-26T16:19:24.026+0000] {logging_mixin.py:190} INFO -  Previous state of the Task instance: queued
[2024-09-26T16:19:24.027+0000] {logging_mixin.py:190} INFO - Current task name:Create_Table_PGdb state:running start_date:2024-09-26 16:19:15.732877+00:00
[2024-09-26T16:19:24.027+0000] {logging_mixin.py:190} INFO - Dag name:Amazon_Book_Data and current dag run status:running
[2024-09-26T16:19:24.028+0000] {taskinstance.py:731} INFO - ::endgroup::
[2024-09-26T16:19:24.028+0000] {sql.py:266} INFO - Executing: 
    CREATE TABLE IF NOT EXISTS amazon_books (
        id SERIAL PRIMARY KEY,
        title TEXT NOT NULL,
        authors TEXT,
        price TEXT,
        rating TEXT
    );
    
[2024-09-26T16:19:24.036+0000] {base.py:84} INFO - Retrieving connection 'Amazon_Books'
[2024-09-26T16:19:24.043+0000] {base.py:84} INFO - Retrieving connection 'Amazon_Books'
[2024-09-26T16:19:24.046+0000] {sql.py:509} INFO - Running statement: 
    CREATE TABLE IF NOT EXISTS amazon_books (
        id SERIAL PRIMARY KEY,
        title TEXT NOT NULL,
        authors TEXT,
        price TEXT,
        rating TEXT
    );
    , parameters: None
[2024-09-26T16:19:24.402+0000] {taskinstance.py:3310} ERROR - Task failed with exception
Traceback (most recent call last):
  File "/home/airflow/.local/lib/python3.12/site-packages/airflow/models/taskinstance.py", line 767, in _execute_task
    result = _execute_callable(context=context, **execute_callable_kwargs)
             ^^^^^^^^^^^^^^^^^^^^^^^^^^^^^^^^^^^^^^^^^^^^^^^^^^^^^^^^^^^^^
  File "/home/airflow/.local/lib/python3.12/site-packages/airflow/models/taskinstance.py", line 733, in _execute_callable
    return ExecutionCallableRunner(
           ^^^^^^^^^^^^^^^^^^^^^^^^
  File "/home/airflow/.local/lib/python3.12/site-packages/airflow/utils/operator_helpers.py", line 252, in run
    return self.func(*args, **kwargs)
           ^^^^^^^^^^^^^^^^^^^^^^^^^^
  File "/home/airflow/.local/lib/python3.12/site-packages/airflow/models/baseoperator.py", line 406, in wrapper
    return func(self, *args, **kwargs)
           ^^^^^^^^^^^^^^^^^^^^^^^^^^^
  File "/home/airflow/.local/lib/python3.12/site-packages/airflow/providers/common/sql/operators/sql.py", line 272, in execute
    output = hook.run(
             ^^^^^^^^^
  File "/home/airflow/.local/lib/python3.12/site-packages/airflow/providers/common/sql/hooks/sql.py", line 456, in run
    self._run_command(cur, sql_statement, parameters)
  File "/home/airflow/.local/lib/python3.12/site-packages/airflow/providers/common/sql/hooks/sql.py", line 514, in _run_command
    cur.execute(sql_statement)
psycopg2.errors.UniqueViolation: duplicate key value violates unique constraint "pg_type_typname_nsp_index"
DETAIL:  Key (typname, typnamespace)=(amazon_books_id_seq, 2200) already exists.

[2024-09-26T16:19:24.420+0000] {logging_mixin.py:190} INFO - Task instance in failure state
[2024-09-26T16:19:24.421+0000] {logging_mixin.py:190} INFO - Task start:2024-09-26 16:19:15.732877+00:00 end:2024-09-26 16:19:24.419360+00:00 duration:8.686483
[2024-09-26T16:19:24.422+0000] {logging_mixin.py:190} INFO - Task:<Task(PostgresOperator): Create_Table_PGdb> dag:<DAG: Amazon_Book_Data> dagrun:<DagRun Amazon_Book_Data @ 2024-06-21 00:00:00+00:00: scheduled__2024-06-21T00:00:00+00:00, state:running, queued_at: 2024-09-26 16:17:52.460035+00:00. externally triggered: False>
[2024-09-26T16:19:24.422+0000] {logging_mixin.py:190} INFO - Failure caused by duplicate key value violates unique constraint "pg_type_typname_nsp_index"
DETAIL:  Key (typname, typnamespace)=(amazon_books_id_seq, 2200) already exists.
[2024-09-26T16:19:24.423+0000] {taskinstance.py:1225} INFO - Marking task as UP_FOR_RETRY. dag_id=Amazon_Book_Data, task_id=Create_Table_PGdb, run_id=scheduled__2024-06-21T00:00:00+00:00, execution_date=20240621T000000, start_date=20240926T161915, end_date=20240926T161924
[2024-09-26T16:19:24.447+0000] {taskinstance.py:340} INFO - ::group::Post task execution logs
[2024-09-26T16:19:24.450+0000] {standard_task_runner.py:124} ERROR - Failed to execute job 21 for task Create_Table_PGdb (duplicate key value violates unique constraint "pg_type_typname_nsp_index"
DETAIL:  Key (typname, typnamespace)=(amazon_books_id_seq, 2200) already exists.
; 1300)
Traceback (most recent call last):
  File "/home/airflow/.local/lib/python3.12/site-packages/airflow/task/task_runner/standard_task_runner.py", line 117, in _start_by_fork
    ret = args.func(args, dag=self.dag)
          ^^^^^^^^^^^^^^^^^^^^^^^^^^^^^
  File "/home/airflow/.local/lib/python3.12/site-packages/airflow/cli/cli_config.py", line 49, in command
    return func(*args, **kwargs)
           ^^^^^^^^^^^^^^^^^^^^^
  File "/home/airflow/.local/lib/python3.12/site-packages/airflow/utils/cli.py", line 115, in wrapper
    return f(*args, **kwargs)
           ^^^^^^^^^^^^^^^^^^
  File "/home/airflow/.local/lib/python3.12/site-packages/airflow/cli/commands/task_command.py", line 483, in task_run
    task_return_code = _run_task_by_selected_method(args, _dag, ti)
                       ^^^^^^^^^^^^^^^^^^^^^^^^^^^^^^^^^^^^^^^^^^^^
  File "/home/airflow/.local/lib/python3.12/site-packages/airflow/cli/commands/task_command.py", line 256, in _run_task_by_selected_method
    return _run_raw_task(args, ti)
           ^^^^^^^^^^^^^^^^^^^^^^^
  File "/home/airflow/.local/lib/python3.12/site-packages/airflow/cli/commands/task_command.py", line 341, in _run_raw_task
    return ti._run_raw_task(
           ^^^^^^^^^^^^^^^^^
  File "/home/airflow/.local/lib/python3.12/site-packages/airflow/utils/session.py", line 97, in wrapper
    return func(*args, session=session, **kwargs)
           ^^^^^^^^^^^^^^^^^^^^^^^^^^^^^^^^^^^^^^
  File "/home/airflow/.local/lib/python3.12/site-packages/airflow/models/taskinstance.py", line 3004, in _run_raw_task
    return _run_raw_task(
           ^^^^^^^^^^^^^^
  File "/home/airflow/.local/lib/python3.12/site-packages/airflow/models/taskinstance.py", line 273, in _run_raw_task
    TaskInstance._execute_task_with_callbacks(
  File "/home/airflow/.local/lib/python3.12/site-packages/airflow/models/taskinstance.py", line 3158, in _execute_task_with_callbacks
    result = self._execute_task(context, task_orig)
             ^^^^^^^^^^^^^^^^^^^^^^^^^^^^^^^^^^^^^^
  File "/home/airflow/.local/lib/python3.12/site-packages/airflow/models/taskinstance.py", line 3182, in _execute_task
    return _execute_task(self, context, task_orig)
           ^^^^^^^^^^^^^^^^^^^^^^^^^^^^^^^^^^^^^^^
  File "/home/airflow/.local/lib/python3.12/site-packages/airflow/models/taskinstance.py", line 767, in _execute_task
    result = _execute_callable(context=context, **execute_callable_kwargs)
             ^^^^^^^^^^^^^^^^^^^^^^^^^^^^^^^^^^^^^^^^^^^^^^^^^^^^^^^^^^^^^
  File "/home/airflow/.local/lib/python3.12/site-packages/airflow/models/taskinstance.py", line 733, in _execute_callable
    return ExecutionCallableRunner(
           ^^^^^^^^^^^^^^^^^^^^^^^^
  File "/home/airflow/.local/lib/python3.12/site-packages/airflow/utils/operator_helpers.py", line 252, in run
    return self.func(*args, **kwargs)
           ^^^^^^^^^^^^^^^^^^^^^^^^^^
  File "/home/airflow/.local/lib/python3.12/site-packages/airflow/models/baseoperator.py", line 406, in wrapper
    return func(self, *args, **kwargs)
           ^^^^^^^^^^^^^^^^^^^^^^^^^^^
  File "/home/airflow/.local/lib/python3.12/site-packages/airflow/providers/common/sql/operators/sql.py", line 272, in execute
    output = hook.run(
             ^^^^^^^^^
  File "/home/airflow/.local/lib/python3.12/site-packages/airflow/providers/common/sql/hooks/sql.py", line 456, in run
    self._run_command(cur, sql_statement, parameters)
  File "/home/airflow/.local/lib/python3.12/site-packages/airflow/providers/common/sql/hooks/sql.py", line 514, in _run_command
    cur.execute(sql_statement)
psycopg2.errors.UniqueViolation: duplicate key value violates unique constraint "pg_type_typname_nsp_index"
DETAIL:  Key (typname, typnamespace)=(amazon_books_id_seq, 2200) already exists.

[2024-09-26T16:19:24.486+0000] {local_task_job_runner.py:266} INFO - Task exited with return code 1
[2024-09-26T16:19:24.501+0000] {taskinstance.py:3900} INFO - 0 downstream tasks scheduled from follow-on schedule check
[2024-09-26T16:19:24.503+0000] {local_task_job_runner.py:245} INFO - ::endgroup::
